Workbook

Sheet Readme & Portfolio Guide
A2: Real Estate Bookkeeping Master Portfolio Dataset
A3: A Comprehensive Dataset Spanning Property Acquisition, Monthly Rental Operations, Bank Feeds, Credit Cards, Property Disposal, and Financial Reporting.
A5: Workbook Color Legend
A6: Cell Style | B6: Hex Code | C6: Meaning / Usage
A7: Input Cell (Editable) | B7: #DCE6F1 | C7: Manual entries or assumptions the user/bookkeeper enters (e.g. initial parameters)
A8: Calculated / Formula | B8: #E2EFDA | C8: Automatically computed values (e.g. totals, margins, ratios, answer keys)
A9: Zebra Stripe / Background | B9: #F2F2F2 | C9: To separate rows in large tables for readability
A10: Section Headers | B10: #4472C4 | C10: Start of a major functional block within the spreadsheet
A11: Table Headers / Grand Totals | B11: #2F5496 | C11: Primary column headers and grand total result lines
A13: How to Use This Dataset for Your Bookkeeping Portfolio
A14: Step 1: Understand the Scenario
A15: You are the bookkeeper for a real estate investment firm that purchased a 4-unit residential building called '123 Maple Street Apartments' on January 15, 2026. After managing the property for six months, the owner decided to take advantage of market appreciation and sold the property on June 30, 2026. This compressed timeline lets you demonstrate standard monthly rental operations AND the complex, high-value transactions of property acquisition and property disposal.
A17: Step 2: Import the Chart of Accounts
A18: Use the 'Chart of Accounts' tab to build or import your accounts in QuickBooks Online (QBO). Real estate bookkeeping is unique because of the asset sub-ledgering structure (separating land from building and improvements) and the escrow/mortgage liability tracking. You can export that sheet as a CSV and import it into QBO.
A20: Step 3: Book the Property Acquisition
A21: Using the Closing Disclosure/Settlement Statement on the 'Property Acquisition & Sale' tab, book the property purchase on January 15, 2026. This requires a Journal Entry that captures the purchase price, escrow closing costs, capitalized loan fees, seller tax credits, and the initial mortgage loan liability. Note how land must be separated as it does not depreciate.
A23: Step 4: Import and Categorize Bank Feeds
A24: The 'Checking Account Feed' and 'Credit Card Feed' tabs contain realistic transaction registries. You can save these sheets as CSV files and import them directly into QBO's bank feed tool. Work through the transactions to categorize them: allocate rental deposits to Rental Income, security deposits to Tenant Security Deposits (liability), property management fees, repairs, utility bills, and monthly mortgage payments (splitting principal and interest).
A26: Step 5: Perform Bank Reconciliation
A27: At the end of each month, reconcile the checking and credit card statements. Note that the Rent Roll tab serves as your supporting sub-ledger to confirm which tenants paid and which accounts are outstanding.
A29: Step 6: Book the Property Sale & Depreciation Recapture
... A36: Upload this workbook to your GitHub. Write a detailed Case Study on LinkedIn explaining how you handled the acquisition, monthly tracking, bank reconciliation, and sale. Post screenshots of your P&L and Balance Sheet. This demonstrates to prospective real estate clients worldwide that you possess deep, specialized knowledge of real estate bookkeeping—far beyond generic data entry.

Sheet Chart of Accounts
A1: Real Estate Specific Chart of Accounts
A2: Import this master list into QuickBooks Online to set up your practice company.
A4: Account Number | B4: Account Name | C4: Account Type | D4: Detail Type | E4: Description / Specific QBO Treatment
A5: 1100 | B5: Business Checking - Rental Operations | C5: Bank | D5: Checking | E5: Primary bank account for receiving rent and paying operating expenses.
A6: 1200 | B6: Tenant Security Deposit Checking (Trust) | C6: Bank | D6: Checking | E6: Separate bank account held in escrow to keep security deposits segregated from operating cash.
A7: 1300 | B7: Prepaid Insurance | C7: Other Current Asset | D7: PrepaidExpenses | E7: Insurance premiums paid in advance, amortized monthly.
A8: 1510 | B8: 123 Maple St - Purchase Price (Property) | C8: Fixed Asset | D8: Non-depreciableLand | E8: Asset account to hold the unadjusted purchase price of the property.
A9: 1520 | B9: 123 Maple St - Land Allocation | C9: Fixed Asset | D9: Non-depreciableLand | E9: Value of the land portion of the purchase (cannot be depreciated).
A10: 1530 | B10: 123 Maple St - Building & Improvements | C10: Fixed Asset | D10: Building | E10: Depreciable portion of the property, including capitalized improvements.
A11: 1540 | B11: 123 Maple St - Capitalized Acquisition Costs | C11: Fixed Asset | D11: Building | E11: Capitalized escrow and title costs that increase the property's tax basis.
A12: 1550 | B12: 123 Maple St - Accumulated Depreciation | C12: Fixed Asset | D12: AccumulatedDepreciation | E12: Contra-asset account tracking cumulative depreciation over time.
A13: 2100 | B13: Accounts Payable | C13: Accounts Payable | D13: AccountsPayable | E13: Unpaid expenses owed to vendors and contractors.
A14: 2200 | B14: Tenant Security Deposits (Held) | C14: Other Current Liability | D14: OtherCurrentLiabilities | E14: Escrow liability account representing refundable deposits owed back to tenants.
A15: 2500 | B15: Mortgage Payable - Commercial Bank of NY | C15: Long Term Liability | D15: NotesPayable | E15: Outstanding balance of the principal mortgage loan on 123 Maple St.
... A30: 8100 | B30: Gain/Loss on Sale of Real Estate | C30: Other Income | D30: OtherMiscellaneousIncome | E30: Special account to record the net capital gain or loss upon disposal of property.

Sheet Property Acquisition & Sale
A1: Property Transactions Details: Acquisition & Sale
A2: This tab acts as the closing disclosure and explains how to book the property purchase and sale via Journal Entries.
A4: PART 1: ACQUISITION SETTLEMENT STATEMENT (JANUARY 15, 2026) | E4: LAND & BUILDING ALLOCATION
A5: Item Description | B5: Debits (Assets/Expenses) | C5: Credits (Liabilities/Equity) | D5: QBO Chart of Accounts Mapping | E5: Category | F5: Amount
A6: Contract Purchase Price (Total Basis) | B6: 850000 | D6: 1510: 123 Maple St - Purchase Price (Fixed Asset) | E6: Land Allocation (17.65%) | F6: 150000
A7: New First Mortgage Loan (Long-Term Liability) | C7: 640000 | D7: 2500: Mortgage Payable (Long Term Liability) | E7: Building & Improvements (82.35%) | F7: 700000
A8: Earnest Money Deposit (Paid from personal funds) | C8: 15000 | D8: 3000: Owner's Capital Investment (Equity) | E8: Capitalized Fees Added to Basis | F8: 11000
A9: Title Search & Legal Escrow Fees | B9: 4500 | D9: 1540: Capitalized Acquisition Costs (Fixed Asset) | E9: Total Property Basis | F9: =SUM(F6:F8)
A10: Recording & Transfer Fees | B10: 500 | D10: 1540: Capitalized Acquisition Costs (Fixed Asset)
A11: Property Tax Prorations (Seller credit to buyer) | C11: 2500 | D11: 5500: Property Tax Expense (Operating Expense Credit)
A12: Prepaid Homeowners Insurance Premium (1 Year) | B12: 2400 | D12: 1300: Prepaid Insurance (Other Current Asset)
A13: Loan Origination & Processing Fee | B13: 6000 | D13: 1540: Capitalized Acquisition Costs (Fixed Asset)
A14: Balance of Cash to Close (Paid from Business Checking) | C14: 205900 | D14: 1100: Business Checking (Bank account outflow)
A15: Totals | B15: =SUM(B6:B13) | C15: =SUM(C6:C13) | D15: Verify that debits equal credits
A16: PROPERTY ACQUISITION JOURNAL ENTRY (JANUARY 15, 2026)
A17: Account Number | B17: Account Name | C17: Debit ($) | D17: Credit ($) | E17: Description / Memo
A18: 1520 | B18: 123 Maple St - Land Allocation | C18: 150000 | D18: 0 | E18: Record Land purchase (non-depreciable)
A19: 1530 | B19: 123 Maple St - Building & Improvements | C19: 700000 | D19: 0 | E19: Record Building purchase (depreciable)
A20: 1540 | B20: 123 Maple St - Capitalized Acquisition Costs | C20: 11000 | D20: 0 | E20: Capitalize closing legal, title, transfer & origination fees
A21: 1300 | B21: Prepaid Insurance | C21: 2400 | D21: 0 | E21: Prepaid property & liability insurance (1 year policy)
A22: 2500 | B22: Mortgage Payable - Commercial Bank | C22: 0 | D22: 640000 | E22: Record new 1st mortgage liability on 123 Maple St
A23: 3000 | B23: Owner's Capital Investment | C23: 0 | D23: 15000 | E23: Record earnest money deposit paid from personal check
A24: 5500 | B24: Property Tax Expense | C24: 0 | D24: 2500 | E24: Apply seller's property tax credit as county tax reduction
A25: 1100 | B25: Business Checking | C25: 0 | D25: 205900 | E25: Record final cash paid from business bank account to close
A26: Totals | C26: =SUM(C18:C25) | D26: =SUM(D18:D25)
A29: PART 2: DISPOSAL / PROPERTY SALE SETTLEMENT STATEMENT (JUNE 30, 2026)
A30: Item Description | B30: Debits (Assets/Expenses) | C30: Credits (Liabilities/Equity) | D30: QBO Chart of Accounts Mapping
A31: Contract Sale Price (Gross Proceeds) | C31: 950000 | D31: 1510/8100: Property disposal transaction | E31: CAPITAL GAIN CALCULATION
A32: Mortgage Payoff Amount (Commercial Bank of NY) | B32: 634950 | D32: 2500: Mortgage Payable (Full liability payoff) | E32: Item | F32: Amount
A33: Real Estate Broker Commissions (6%) | B33: 57000 | D33: 8100: Reduction in Net Capital Gain (Disposal costs) | E33: Contract Sale Price | F33: 950000
A34: Title Transfer & Escrow Closing Fees | B34: 3000 | D34: 8100: Reduction in Net Capital Gain (Disposal costs) | E34: Less: Commissions & Fees | F34: -60000
A35: Property Tax Prorations (Paid to county at closing) | B35: 2400 | D35: 5500: Property Tax Expense (Half-year prorated taxes) | E35: Net Sales Realization | F35: =SUM(F33:F34)
A36: Prepaid Insurance Refund Received (Pro-rated) | C36: 1300 | D36: 1300: Write-off Prepaid Insurance / Bank Deposit | E36: Less: Original Asset Cost Basis | F36: -861000
A37: Net Cash Proceeds to Business Checking | B37: 253950 | D37: 1100: Business Checking (Bank account inflow) | E37: Plus: Accumulated Depreciation | F37: 11676.5
A38: Totals | B38: =SUM(B31:B37) | C38: =SUM(C31:C37) | D38: Verify that debits equal credits | E38: Adjusted Tax Cost Basis | F38: =SUM(F36:F37)
E39: Net Capital Gain on Sale | F39: =F35-F38
A41: PROPERTY SALE JOURNAL ENTRY (JUNE 30, 2026)
A42: Account Number | B42: Account Name | C42: Debit ($) | D42: Credit ($) | E42: Description / Memo
A43: 1100 | B43: Business Checking | C43: 253950 | D43: 0 | E43: Record net cash proceeds received from title escrow
A44: 2500 | B44: Mortgage Payable - Commercial Bank | C44: 634950 | D44: 0 | E44: Remove remaining mortgage liability paid off from sales price
...

Sheet Checking Account Feed
A1: Business Checking Account Bank Feed
A2: This table matches standard bank feed exports (QBO CSV import format). Practice categorizing these in QBO!
A4: Date | B4: Description / Payee | C4: Amount ($) | D4: Account Mapping Guidance | E4: Class / Property Tag | F4: Transaction Type
A5: 2026-01-02 | B5: Owner Initial Contribution - Deposit | C5: 15000 | D5: 3000: Owner's Capital Investment (Equity) | E5: 123 Maple St Apartments | F5: Deposit
A6: 2026-01-10 | B6: Owner Contribution - Cash to Close | C6: 210000 | D6: 3000: Owner's Capital Investment (Equity) | E6: 123 Maple St Apartments | F6: Deposit
A7: 2026-01-15 | B7: Acquisition Wire - Cash to Close (Escrow Co) | C7: -205900 | D7: JE: Recording property acquisition | E7: 123 Maple St Apartments | F7: Payment
A8: 2026-01-18 | B8: Apex Property Mgmt - Security Deposit Unit 1A | C8: 1800 | D8: 2200: Tenant Security Deposits (Liability) | E8: Unit 1A | F8: Deposit
A9: 2026-01-18 | B9: Apex Property Mgmt - Security Deposit Unit 1B | C9: 1800 | D9: 2200: Tenant Security Deposits (Liability) | E9: Unit 1B | F9: Deposit
A10: 2026-01-18 | B10: Apex Property Mgmt - Security Deposit Unit 2A | C10: 1800 | D10: 2200: Tenant Security Deposits (Liability) | E10: Unit 2A | F10: Deposit
A11: 2026-01-18 | B11: Apex Property Mgmt - Security Deposit Unit 2B | C11: 1800 | D11: 2200: Tenant Security Deposits (Liability) | E11: Unit 2B | F11: Deposit
A12: 2026-01-18 | B12: Apex Property Mgmt - Prorated Jan Rent Unit 1A | C12: 900 | D12: 4100: Rental Income | E12: Unit 1A | F12: Deposit
A13: 2026-01-18 | B13: Apex Property Mgmt - Prorated Jan Rent Unit 1B | C13: 900 | D13: 4100: Rental Income | E13: Unit 1B | F13: Deposit
A14: 2026-01-18 | B14: Apex Property Mgmt - Prorated Jan Rent Unit 2A | C14: 900 | D14: 4100: Rental Income | E14: Unit 2A | F14: Deposit
A15: 2026-01-18 | B15: Apex Property Mgmt - Prorated Jan Rent Unit 2B | C15: 900 | D15: 4100: Rental Income | E15: Unit 2B | F15: Deposit
A16: 2026-01-20 | B16: Transfer to Sec Deposit Escrow Bank Account | C16: -7200 | D16: 1200: Trust Checking (Transfer between bank accounts) | E16: 123 Maple St Apartments | F16: Payment
... A51: 2026-06-30 | B51: Acquisition Title Escrow Co - Net Sale Proceeds | C51: 253950 | D51: JE: Property disposal transaction net deposit | E51: 123 Maple St Apartments | F51: Deposit

Sheet Credit Card Feed
A1: Business Credit Card Statement / Feed
A2: Expenses charged to the business card (repaired items, office supplies, software, marketing).
A4: Date | B4: Description / Payee | C4: Amount ($) | D4: Account Mapping Guidance | E4: Class / Property Tag | F4: Payment / Charge
A5: 2026-01-20 | B5: Staples - Office Supplies & Paperwork folders | C5: -85 | D5: 5700: Professional & Software Fees (Office Supplies) | E5: 123 Maple St Apartments | F5: Charge
A6: 2026-01-25 | B6: Intuit QuickBooks - Monthly Software Subscription | C6: -75 | D6: 5700: Professional & Software Fees (Software) | E6: 123 Maple St Apartments | F6: Charge
A7: 2026-01-28 | B7: Zillow Premier Agent - Tenant Acquisition Rental Listing | C7: -150 | D7: 5800: Marketing & Advertising | E7: 123 Maple St Apartments | F7: Charge
A8: 2026-02-15 | B8: Home Depot - Smoke Detector Batteries & LED bulbs | C8: -45 | D8: 5200: Repairs & Maintenance | E8: 123 Maple St Apartments | F8: Charge
A9: 2026-02-25 | B9: Intuit QuickBooks - Monthly Software Subscription | C9: -75 | D9: 5700: Professional & Software Fees (Software) | E9: 123 Maple St Apartments | F9: Charge
A10: 2026-03-22 | B10: Ace Hardware - Replacement lockset Unit 2B | C10: -65 | D10: 5200: Repairs & Maintenance | E10: Unit 2B | F10: Charge
A11: 2026-03-25 | B11: Intuit QuickBooks - Monthly Software Subscription | C11: -75 | D11: 5700: Professional & Software Fees (Software) | E11: 123 Maple St Apartments | F11: Charge
A12: 2026-04-15 | B12: Local Print Shop - Rental flyers & Marketing brochures | C12: -120 | D12: 5800: Marketing & Advertising | E12: 123 Maple St Apartments | F12: Charge
A13: 2026-04-25 | B13: Intuit QuickBooks - Monthly Software Subscription | C13: -75 | D13: 5700: Professional & Software Fees (Software) | E13: 123 Maple St Apartments | F13: Charge
A14: 2026-04-28 | B14: Business CC Autopay Payment - Received | C14: 535 | D14: Transfer: CC Autopay Payment from Checking | E14: 123 Maple St Apartments | F14: Payment
A15: 2026-05-25 | B15: Intuit QuickBooks - Monthly Software Subscription | C15: -75 | D15: 5700: Professional & Software Fees (Software) | E15: 123 Maple St Apartments | F15: Charge
A16: 2026-05-28 | B16: Facebook Ads - Rental Marketing Campaign | C16: -110 | D16: 5800: Marketing & Advertising | E16: 123 Maple St Apartments | F16: Charge
... A18: 2026-06-30 | B18: Business CC Settlement Payoff - Received | C18: 490 | D18: Transfer: Final CC Payoff before Closing Accounts | E18: 123 Maple St Apartments | F18: Payment

Sheet Rent Roll & Tenant Ledger
A1: Property Rent Roll & Tenant Sub-Ledger
A2: Rent roll as of June 30, 2026 for 123 Maple Street Apartments. Use this to verify tenant details and rent collection.
A4: Unit # | B4: Tenant Name | C4: Monthly Rent ($) | D4: Security Deposit ($) | E4: Lease Start Date | F4: Lease End Date | G4: Jan Rent Status | H4: Feb Rent Status | I4: Mar Rent Status | J4: Apr Rent Status | K4: May Rent Status | L4: Jun Rent Status
A5: Unit 1A | B5: Jane Doe | C5: 1800 | D5: 1800 | E5: 2026-01-15 | F5: 2027-01-31 | G5: Paid (Prorated) | H5: Paid | I5: Paid | J5: Paid | K5: Paid | L5: Paid
A6: Unit 1B | B6: John Smith | C6: 1800 | D6: 1800 | E6: 2026-01-15 | F6: 2027-01-31 | G6: Paid (Prorated) | H6: Paid | I6: Paid | J6: Paid | K6: Paid | L6: Paid
A7: Unit 2A | B7: Alice Johnson | C7: 1800 | D7: 1800 | E7: 2026-01-15 | F7: 2027-01-31 | G7: Paid (Prorated) | H7: Paid | I7: Paid | J7: Paid | K7: Paid | L7: Paid
A8: Unit 2B | B8: Bob Williams | C8: 1800 | D8: 1800 | E8: 2026-01-15 | F8: 2027-01-31 | G8: Paid (Prorated) | H8: Paid | I8: Paid | J8: Paid | K8: Paid + $100 Late Fee | L8: Paid
A9: Totals | C9: =SUM(C5:C8) | D9: =SUM(D5:D8)

Sheet Target Financial Reports
A1: Target Financial Reports (Answer Key)
A2: This represents the completed, reconciled Profit & Loss and Balance Sheet for the entire 6-month period.
A4: PROFIT & LOSS STATEMENT: 123 MAPLE STREET APARTMENTS
A5: January 1, 2026 - June 30, 2026
A7: Category / Account | B7: Jan 2026 | C7: Feb 2026 | D7: Mar 2026 | E7: Apr 2026 | F7: May 2026 | G7: Jun 2026 | H7: Operating Total | I7: Property Sale* | J7: Grand Total
A8: Revenue
A9: Rental Income | B9: 3600 | C9: 7200 | D9: 7200 | E9: 7200 | F9: 7200 | G9: 7200 | H9: =SUM(B9:G9) | I9: 0 | J9: =H9+I9
A10: Late Fee Income | B10: 0 | C10: 0 | D10: 0 | E10: 0 | F10: 100 | G10: 0 | H10: =SUM(B10:G10) | I10: 0 | J10: =H10+I10
A11: Total Revenue | B11: =SUM(B9:B10) | C11: =SUM(C9:C10) | D11: =SUM(D9:D10) | E11: =SUM(E9:E10) | F11: =SUM(F9:F10) | G11: =SUM(G9:G10) | H11: =SUM(H9:H10) | I11: =SUM(I9:I10) | J11: =SUM(J9:J10)
A12: Expenses
A13: Property Management Fees | B13: 288 | C13: 576 | D13: 576 | E13: 576 | F13: 584 | G13: 576 | H13: =SUM(B13:G13) | I13: 0 | J13: =H13+I13
A14: Repairs & Maintenance | B14: 0 | C14: 45 | D14: 515 | E14: 650 | F14: 0 | G14: 350 | H14: =SUM(B14:G14) | I14: 0 | J14: =H14+I14
A15: Utilities | B15: 0 | C15: 650 | D15: 0 | E15: 665 | F15: 0 | G15: 700 | H15: =SUM(B15:G15) | I15: 0 | J15: =H15+I15
A16: Insurance Expense | B16: 100 | C16: 200 | D16: 200 | E16: 200 | F16: 200 | G16: 200 | H16: =SUM(B16:G16) | I16: 0 | J16: =H16+I16
A17: Property Tax Expense | B17: -2500 | C17: 0 | D17: 0 | E17: 0 | F17: 0 | G17: 2400 | H17: =SUM(B17:G17) | I17: 2400 | J17: =H17+I17
A18: Mortgage Interest Expense | B18: 0 | C18: 3200 | D18: 3195 | E18: 3190 | F18: 3185 | G18: 3180 | H18: =SUM(B18:G18) | I18: 0 | J18: =H18+I18
A19: Professional & Software Fees | B19: 160 | C19: 75 | D19: 75 | E19: 75 | F19: 75 | G19: 75 | H19: =SUM(B19:G19) | I19: 0 | J19: =H19+I19
A20: Marketing & Advertising | B20: 150 | C20: 0 | D20: 0 | E20: 120 | F20: 110 | G20: 0 | H20: =SUM(B20:G20) | I20: 0 | J20: =H20+I20
A21: Depreciation Expense | B21: 1061.5 | C21: 2123 | D21: 2123 | E21: 2123 | F21: 2123 | G21: 2123 | H21: =SUM(B21:G21) | I21: 0 | J21: =H21+I21
A22: Total Expenses | B22: =SUM(B13:B21) | C22: =SUM(C13:C21) | D22: =SUM(D13:D21) | E22: =SUM(E13:E21) | F22: =SUM(F13:F21) | G22: =SUM(G13:G21) | H22: =SUM(H13:H21) | I22: =SUM(I13:I21) | J22: =SUM(J13:J21)
A23: Net Operating Income (NOI) | B23: =B11-B22 | C23: =C11-C22 | D23: =D11-D22 | E23: =E11-E22 | F23: =F11-F22 | G23: =G11-G22 | H23: =H11-H22 | I23: =I11-I22 | J23: =J11-J22
A24: Other Income / (Expenses)
A25: Gain on Sale of Real Estate | B25: 0 | C25: 0 | D25: 0 | E25: 0 | F25: 0 | G25: 0 | H25: 0 | I25: 40676.5 | J25: 40676.5
A26: Net Income | B26: =B23+B25 | C26: =C23+C25 | D26: =D23+D25 | E26: =E23+E25 | F26: =F23+F25 | G26: =G23+G25 | H26: =H23+H25 | I26: =I23+I25 | J26: =J23+J25
A27: *Note: The Property Sale column records transaction-specific entries on disposal (June 30, 2026).
A31: BALANCE SHEET STATEMENT: 123 MAPLE STREET APARTMENTS
A32: Comparison Pre-Sale vs. Post-Sale (Asset and Liability liquidations)
A34: Account Name / Description | B34: As of May 31, 2026 (Pre-Sale) | C34: As of June 30, 2026 (Post-Sale) | D34: Specific Balance Sheet Ledger Notes
A36: ASSETS
A37: Current Assets
A38: Business Checking - Operating Cash | B38: 28224 | C38: 276684 | D38: Includes net operations cash, less owner draw, plus property sale proceeds
A39: Tenant Security Deposit Checking (Trust) | B39: 7200 | C39: 0 | D39: Segregated trust funds (fully refunded to tenants on sale date)
A40: Prepaid Insurance | B40: 1300 | C40: 0 | D40: Residual prepaid insurance is written off/credited on sale
A41: Total Current Assets | B41: =SUM(B38:B40) | C41: =SUM(C38:C40) | D41: Total liquid current assets
A42: Fixed Assets
A43: 123 Maple St - Property Purchase Price | B43: 850000 | C43: 0 | D43: Fixed Asset cost written off upon sale on June 30
A44: 123 Maple St - Capitalized Acquisition Costs | B44: 11000 | C44: 0 | D44: Escrow capitalized fees written off upon sale
A45: 123 Maple St - Accumulated Depreciation | B45: -11676.5 | C45: 0 | D45: Contra-asset written off upon property sale
A46: Total Fixed Assets | B46: =SUM(B43:B45) | C46: =SUM(C43:C45) | D46: Net Book Value of the property
A47: TOTAL ASSETS | B47: =B41+B46 | C47: =C41+C46 | D47: Total Assets of the business
...

Sheet Key Performance Indicators
A1: Real Estate Key Performance Indicators (KPIs)
A2: These standard real estate metrics measure the performance of 123 Maple Street Apartments based on operations.
A4: KPI Metric | B4: Formula / Definition | C4: Calculated Value | D4: Industry Benchmarks & Strategic Insight
A5: Net Operating Income (NOI) | B5: Revenues - Operating Expenses (excl. Debt & Depreciation) | C5: ='Target Financial Reports'!H11 - ('Target Financial Reports'!H22 - 'Target Financial Reports'!H18 - 'Target Financial Reports'!H21) | D5: Measures the operational profitability of the property before financing or taxes. The lifeblood of real estate valuation.
A6: Capitalization Rate (Cap Rate) | B6: Annualized NOI / Purchase Price | C6: =( ('Target Financial Reports'!H11 - ('Target Financial Reports'!H22 - 'Target Financial Reports'!H18 - 'Target Financial Reports'!H21)) * 2 ) / 'Property Acquisition & Sale'!B6 | D6: The unlevered rate of return on the property. Higher Cap Rates (6-8%) represent better operational returns relative to asset cost.
A7: Cash-on-Cash Return (CoC) | B7: Annualized Cash Flow / Initial Equity Invested | C7: =( ( ('Target Financial Reports'!H11 - ('Target Financial Reports'!H22 - 'Target Financial Reports'!H21)) - 5050 ) * 2 ) / 'Target Financial Reports'!B58 | D7: Measures cash return on cash invested. Cash Flow here is Operating Income minus debt payments, annualized, over initial cash down payment.
A8: Debt Service Coverage Ratio (DSCR) | B8: NOI / Annual Debt Service (Principal + Interest) | C8: =('Target Financial Reports'!H11 - ('Target Financial Reports'!H22 - 'Target Financial Reports'!H18 - 'Target Financial Reports'!H21)) / ( 'Target Financial Reports'!H18 + 5050 ) | D8: Lenders look for a DSCR > 1.25 to ensure the property generates enough income to safely cover mortgage payments. Principal paid was $5,050.
A9: Operating Expense Ratio (OER) | B9: Total Operating Expenses / Gross Revenues | C9: =('Target Financial Reports'!H22 - 'Target Financial Reports'!H18 - 'Target Financial Reports'!H21) / 'Target Financial Reports'!H11 | D9: Measures operating efficiency. Standard OER ranges from 35% to 50%. A lower OER indicates highly efficient property management.
A10: Gross Rent Multiplier (GRM) | B10: Purchase Price / Annual Gross Rent | C10: ='Property Acquisition & Sale'!B6 / ('Target Financial Reports'!H9 * 2) | D10: A quick metric for property comparison. Lower GRM indicates a more attractive price relative to gross income potential.
